Workbook

Sheet Overview
A1: HR Change + Orchestration — Build Blueprint
A2: Sprints, gates and progress. Mint cells are inputs; everything else is calculated.
A4: Sprint 0 start date | B4: =TODAY() -> 46303 | C4: ← type your real start date (a Monday)
A6: Sprint | B6: Name | C6: Phase | D6: Weeks | E6: Start | F6: End | G6: Steps | H6: Done | I6: % done | J6: Gate | K6: Gate status
A7: S0 | B7: Foundations | C7: Crawl | D7: 1 | E7: =B4 -> 46303 | F7: =IF(OR(E7="",D7=0),"",E7+D7*7-1) -> 46309 | G7: =COUNTIF('Build Steps'!$B:$B,A7) -> 14 | H7: =COUNTIFS('Build Steps'!$B:$B,A7,'Build Steps'!$J:$J,"Done") -> 0 | I7: =IF(G7=0,"",H7/G7) -> 0 | J7: G0 — Ready to build | K7: Not started
A8: S1 | B8: Crawl — Path E end to end | C8: Crawl | D8: 2 | E8: =IF(F7="","",F7+1) -> 46310 | F8: =IF(OR(E8="",D8=0),"",E8+D8*7-1) -> 46323 | G8: =COUNTIF('Build Steps'!$B:$B,A8) -> 22 | H8: =COUNTIFS('Build Steps'!$B:$B,A8,'Build Steps'!$J:$J,"Done") -> 0 | I8: =IF(G8=0,"",H8/G8) -> 0 | J8: G1 — Plumbing proven | K8: Not started
A9: S2 | B9: Crawl complete — Template I pilot + front door live | C9: Crawl | D9: 2 | E9: =IF(F8="","",F8+1) -> 46324 | F9: =IF(OR(E9="",D9=0),"",E9+D9*7-1) -> 46337 | G9: =COUNTIF('Build Steps'!$B:$B,A9) -> 14 | H9: =COUNTIFS('Build Steps'!$B:$B,A9,'Build Steps'!$J:$J,"Done") -> 0 | I9: =IF(G9=0,"",H9/G9) -> 0 | J9: G2 — Front door live | K9: Not started
A10: S3 | B10: Walk — Approvals B/C/F + checklist progress | C10: Walk | D10: 2 | E10: =IF(F9="","",F9+1) -> 46338 | F10: =IF(OR(E10="",D10=0),"",E10+D10*7-1) -> 46351 | G10: =COUNTIF('Build Steps'!$B:$B,A10) -> 5 | H10: =COUNTIFS('Build Steps'!$B:$B,A10,'Build Steps'!$J:$J,"Done") -> 0 | I10: =IF(G10=0,"",H10/G10) -> 0 | J10: G3 — Approvals live | K10: Not started
A11: S4 | B11: Walk — Daily digest, cutoff reminder, hardening | C11: Walk | D11: 2 | E11: =IF(F10="","",F10+1) -> 46352 | F11: =IF(OR(E11="",D11=0),"",E11+D11*7-1) -> 46365 | G11: =COUNTIF('Build Steps'!$B:$B,A11) -> 5 | H11: =COUNTIFS('Build Steps'!$B:$B,A11,'Build Steps'!$J:$J,"Done") -> 0 | I11: =IF(G11=0,"",H11/G11) -> 0 | J11: G4 — Operational | K11: Not started
A12: S5 | B12: Walk — Downstream actions (dependency-driven) | C12: Walk | D12: 2 | E12: =IF(F11="","",F11+1) -> 46366 | F12: =IF(OR(E12="",D12=0),"",E12+D12*7-1) -> 46379 | G12: =COUNTIF('Build Steps'!$B:$B,A12) -> 4 | H12: =COUNTIFS('Build Steps'!$B:$B,A12,'Build Steps'!$J:$J,"Done") -> 0 | I12: =IF(G12=0,"",H12/G12) -> 0 | J12: G5 — per item | K12: Not started
A13: S6 | B13: Run — Self-service + full audit | C13: Run | D13: 0 | E13: =IF(F12="","",F12+1) -> 46380 | F13: =IF(OR(E13="",D13=0),"",E13+D13*7-1) | G13: =COUNTIF('Build Steps'!$B:$B,A13) -> 5 | H13: =COUNTIFS('Build Steps'!$B:$B,A13,'Build Steps'!$J:$J,"Done") -> 0 | I13: =IF(G13=0,"",H13/G13) -> 0 | J13: Ongoing | K13: Not started
A14: Total | G14: =SUM(G7:G13) -> 69 | H14: =SUM(H7:H13) -> 0 | I14: =IF(G14=0,"",H14/G14) -> 0
A16: How to use this workbook:
A17: 1. Set the start date above. Sprint dates follow (S6 is ongoing).
A18: 2. Work the 'Build Steps' tab top to bottom. Set Status as you go — progress updates here.
A19: 3. Each sprint ends at a gate (Gates tab). Don't start the next sprint until every gate line is Passed.
A20: 4. Run the tests named in each sprint (Test Pack tab). Record Pass/Fail.
A21: 5. The Word document 'HR Change Blueprint' has the same steps with full explanations.

Sheet Roadmap
A1: Roadmap — sprints and gates
A2: Crawl → Walk → Run, as in the project plan.
A4: Sprint | B4: Name | C4: Phase | D4: Start | E4: End | F4: Goal | G4: Entry criteria | H4: Gate | I4: Gate criteria
A5: S0 | B5: Foundations | C5: Crawl | D5: =Overview!E7 -> 46303 | E5: =Overview!F7 -> 46309 | F5: Reference workbook, the one list, permissions, form, views, connections. | G5: Plan approved; this kit downloaded. | H5: G0 — Ready to build | I5: • D3, D5, D6 confirmed by CJ • Field list signed off with Johanna • Reference workbook uploaded and Settings filled • List built: all columns, choices, required fields, show/hide formulas, views • T21 passed (non-HR account sees only own requests)
A6: S1 | B6: Crawl — Path E end to end | C6: Crawl | D6: =Overview!E8 -> 46310 | E6: =Overview!F8 -> 46323 | F6: Flow 1 Intake, Flow 2 Checklist Router, Flow 4 Completion Auto-Comment. Proven on E. | G6: G0 passed. | H6: G1 — Plumbing proven | I6: • T01–T06 pass • One live E submission by Johanna closed end to end • A failure alert email received from a Catch block (any test) • Flows owned by the HR/service account, not a personal one
A7: S2 | B7: Crawl complete — Template I pilot + front door live | C7: Crawl | D7: =Overview!E9 -> 46324 | E7: =Overview!F9 -> 46337 | F7: Flow 5 Approval Routing (HR stage for I), Flow 3 Payroll Notification, all checklists live, front door launched. | G7: G1 passed. | H7: G2 — Front door live | I7: • T07–T13 pass • First real I case approved, earning entered, resolved, Payroll FYI posted • Form pinned in #lane-people-talent; manager comms sent • HR mailbox auto-reply points to the form
A8: S3 | B8: Walk — Approvals B/C/F + checklist progress | C8: Walk | D8: =Overview!E10 -> 46338 | E8: =Overview!F10 -> 46351 | F8: Approval chains switched on from Excel; Flow 6 Checklist Progress; UAT with Johanna. | G8: G2 passed; approval matrix signed off. | H8: G3 — Approvals live | I8: • Approval matrix signed off; Approvers table filled per region • T14–T17 and T22 pass • UAT with Johanna on every path A1–I
A9: S4 | B9: Walk — Daily digest, cutoff reminder, hardening | C9: Walk | D9: =Overview!E11 -> 46352 | E9: =Overview!F11 -> 46365 | F9: Flow 7; exception drill; two weeks of steady operation. | G9: G3 passed. | H9: G4 — Operational | I9: • T18–T20 pass • Two weeks of digests reviewed • No request handled outside the list in those two weeks • SLA baseline reviewed (All Open by SLA / Recently Resolved)
A10: S5 | B10: Walk — Downstream actions (dependency-driven) | C10: Walk | D10: =Overview!E12 -> 46366 | E10: =Overview!F12 -> 46379 | F10: Jira, offboarding distro, Word letters, Monday board — each only when its dependency is confirmed. | G10: G4 passed; each item's dependency confirmed. | H10: G5 — per item | I10: • Dependency confirmed in writing • Built and tested on a test request • Checklist step updated to show it is automated (Auto column)
A11: S6 | B11: Run — Self-service + full audit | C11: Run | D11: =Overview!E13 -> 46380 | E11: =Overview!F13 | F11: Manager self-service form, dashboard, in-Slack approvals, Paycor iPaaS, holiday-aware SLA. | G11: G5 items as available. | H11: Ongoing | I11: • Each item ships with its own test cases and a rollback note

Sheet Build Steps
A1: Build Steps
A2: Every step in order. Status is the only column you need to update (plus Done on / Notes).
A4: ID | B4: Sprint | C4: Area | D4: Step | E4: Where | F4: Do | G4: Paste / settings | H4: Check | I4: Owner | J4: Status | K4: Done on | L4: Notes
A5: S0-01 | B5: S0 | C5: Decisions | D5: Confirm the open design decisions | E5: Decisions tab | F5: • Review D3 (front door), D5 (Template I: Payroll verifier, not gate), D6 (Manager person field). • Mark each Confirmed / Changed in the Decisions tab. | H5: D3, D5, D6 no longer say 'Confirm'. | I5: CJ | J5: Not started
A6: S0-02 | B6: S0 | C6: Excel | D6: Store the reference workbook | E6: People Ops SharePoint site → Documents | F6: • Create a folder 'HR Change' and upload HR Change Reference.xlsx. • Folder → Manage access: HR owners can edit; everyone else no access. • Read the About sheet: never rename a table (tblSettings, tblChangeTypes, tblChecklist, tblApprovers) or a column header. | H6: The file opens in Excel for the web and Table Design shows the four table names. | I6: CJ | J6: Not started
A7: S0-03 | B7: S0 | C7: Excel | D7: Fill in Settings | E7: HR Change Reference.xlsx → Settings | F7: • Set TimeZone, CutoffDay1, CutoffDay2 (your real payroll cutoffs), ReminderBusinessDays and AdminEmail. • Leave IntakeFormUrl for S0-14. | H7: No '<' placeholders left except IntakeFormUrl. | I7: Johanna | J7: Not started
A8: S0-04 | B8: S0 | C8: Excel | D8: Review Change Types | E8: HR Change Reference.xlsx → Change Types | F8: • Check SLA days and the Due Date Rule for every type (Business days / Effective date / None). • Set DefaultAssigneeEmail where a type always goes to the same person (G → CJ is pre-filled). • Leave ApprovalChain blank for B, C, F until Sprint 3 (decision D13). I = 'HR' (pilot). • Decide Sensitive for H (A2 and G are Yes). | H8: Every row has Code, ChangeType, DueDateRule; Yes/No columns contain only Yes or No. | I8: Johanna | J8: Not started
A9: S0-05 | B9: S0 | C9: Excel | D9: Review the checklists against the SOP | E9: HR Change Reference.xlsx → Checklists | F9: • Walk A1–I with Johanna. Edit Task / Details / Owner as needed. Keep Step as two digits (01, 02 …). • Auto: 'approval' = ticked by the approvals flow; 'resolution' = ticked when the case is resolved. AfterApproval = Yes shows 🔒. | H9: Johanna signs off each change type's steps. | I9: Johanna | J9: Not started
A10: S0-06 | B10: S0 | C10: Excel | D10: Draft the Approvers table | E10: HR Change Reference.xlsx → Approvers | F10: • One row per Role (Regional, HR, Payroll) and Region. Region '*' = default for any region. • Region values must match the list's Region choices exactly. | H10: An HR row with Region '*' and Active = Yes exists (needed for the I pilot). | I10: CJ | J10: Not started
A11: S0-07 | B11: S0 | C11: SharePoint | D11: Create the list from CSV | E11: Site → + New → List → From CSV → HR-Change-Requests.csv | F11: • Keep the headers exactly (no spaces = internal names the flows use). • In the preview, set each column type per the List Fields tab. • Name the list 'HR Change Requests' → Create. Delete the SAMPLE row. | H11: List settings → Columns shows internal names without spaces (hover a column: Field=EmployeeName). | I11: Johanna | J11: Not started
A12: S0-08 | B12: S0 | C12: SharePoint | D12: Finish the choice columns | E12: List → column header → Column settings → Edit | F12: • For every Choice column, paste the full choice list from the List Fields tab (one per line). • Defaults: Status = 0-New, ApprovalStatus = Not required. | H12: New form shows all 11 Change Type values. | I12: Johanna | J12: Not started
A13: S0-09 | B13: S0 | C13: SharePoint | D13: Add the three Person columns | E13: List → + Add column → Person | F13: • Manager (required), Assignee, RequestedBy — type the name without spaces first; rename the display name afterwards if you like. | H13: All three appear in the New form / list settings. | I13: Johanna | J13: Not started
A14: S0-10 | B14: S0 | C14: SharePoint | D14: Required fields + permissions | E14: List settings | F14: • Required: EmployeeName, EmployeeId, Manager, ChangeType, EffectiveDate. • Advanced settings → Read access: 'Read items that were created by the user'; Create and Edit access: 'Create items and edit items that were created by the user'. • HR team: Full Control (or Edit + Override List Behaviors) so they see everything. | H14: Test T21 with a non-HR colleague. | I14: CJ | J14: Not started
A15: S0-11 | B15: S0 | C15: SharePoint | D15: Show/hide formulas on the form | E15: List → + New → Edit form (pencil) → Edit columns → column ⋯ → Edit conditional formula | F15: • Paste the 'Show formula' from the List Fields tab for every Conditional and Case column. • Drag the universal fields to the top in Slack-form order: Employee Name, Employee ID, Manager, Change Type, Effective Date, Region, Additional Notes. | H15: Choosing 'C — Comp Change' shows New Rate + Effective Pay Period only; case fields are hidden on New. | I15: Johanna | J15: Not started
A16: S0-12 | B16: S0 | C16: SharePoint | D16: Create the workbench views | E16: List → All Items → Create new view | F16: • Create the 8 views on the Views tab (filters, sort/group, columns). | H16: 'Needs Attention Today' and 'Exceptions' exist. | I16: Johanna | J16: Not started
... A19: S1-01 | B19: S1 | C19: Flow 1 | D19: Create 'HR Change - 1 Intake Notification' | E19: My flows → + New flow → Automated cloud flow | F19: • Trigger: SharePoint — When an item is created · Site: People Ops · List: HR Change Requests. • Add Control → Scope, rename it 'Try'. Build every following action INSIDE Try. | H19: Saved with trigger + empty Try. | I19: Johanna | J19: Not started
A20: S1-02 | B20: S1 | C20: Flow 1 | D20: Add the standard opening block | E20: Inside Try | F20: • Add the six actions of the Standard opening block (Appendix A), renamed exactly. | G20: Settings row (Excel Online (Business) → List rows present in a table): Location: your People Ops site · Document Library: Documents · File: HR Change/HR Change Reference.xlsx · Table: tblSettings Settings (Compose): first(outputs('Settings_row')?['body/value']) Code (Compose): first(split(triggerBody()?['ChangeType']?['Value'], ' ')) Change type row (Excel → List rows present in a table) — Table: tblChangeTypes · Filter Query:: Code eq '@{outputs('Code')}' Config (Compose): first(outputs('Change_type_row')?['body/value']) Request ID (Compose): concat(outputs('Settings')?['RequestPrefix'], formatNumber(triggerBody()?['ID'], '000000')) | H20: Run once (Test → Manually, then create an E request): Config shows the E row. | I20: Johanna | J20: Not started
A21: S1-03 | B21: S1 | C21: Flow 1 | D21: SLA due date | E21: Inside Try, after Request ID | F21: • Four Compose actions, renamed as shown. | G21: Submitted Local: convertFromUtc(triggerBody()?['Created'], outputs('Settings')?['TimeZone']) SLA Start (weekend submissions start Monday): addDays(startOfDay(outputs('Submitted_Local')), if(equals(dayOfWeek(outputs('Submitted_Local')), 6), 2, if(equals(dayOfWeek(outputs('Submitted_Local')), 0), 1, 0))) SLA Days: if(empty(outputs('Config')?['SLABusinessDays']), 0, int(outputs('Config')?['SLABusinessDays'])) SLA Due Date: if(equals(outputs('Config')?['DueDateRule'], 'Effective date'), formatDateTime(coalesce(triggerBody()?['LastDay'], triggerBody()?['EffectiveDate']), 'yyyy-MM-dd'), if(equals(outputs('SLA_Days'), 0), null, formatDateTime(addDays(outputs('SLA_Start'), add(add(mul(div(outputs('SLA_Days'), 5), 7), mod(outputs('SLA_Days'), 5)), if(greater(add(dayOfWeek(outputs('SLA_Start')), mod(outputs('SLA_Days'), 5)), 5), 2, 0))), 'yyyy-MM-dd'))) | H21: E submitted Monday → SLA Due Date = Tuesday. | I21: Johanna | J21: Not started
A22: S1-04 | B22: S1 | C22: Flow 1 | D22: Pay period + cutoff flag (used by type I) | E22: Inside Try | F22: • Four Compose actions. Harmless for other change types. | G22: Pay Period Date: coalesce(triggerBody()?['StartDate'], triggerBody()?['EffectiveDate']) Pay Period: concat(formatDateTime(outputs('Pay_Period_Date'), 'yyyy-MM'), if(lessOrEquals(dayOfMonth(outputs('Pay_Period_Date')), 15), ' (1-15)', ' (16-EOM)')) Cutoff Date: addDays(startOfMonth(outputs('Pay_Period_Date')), sub(int(if(lessOrEquals(dayOfMonth(outputs('Pay_Period_Date')), 15), outputs('Settings')?['CutoffDay1'], outputs('Settings')?['CutoffDay2'])), 1)) After Cutoff: and(equals(outputs('Code'), 'I'), greater(ticks(outputs('Submitted_Local')), ticks(addDays(outputs('Cutoff_Date'), 1)))) | H22: For E: After Cutoff = false. | I22: Johanna | J22: Not started
A23: S1-05 | B23: S1 | C23: Flow 1 | D23: Write ID, title and SLA back to the item | E23: Inside Try → SharePoint → Update item | F23: • List: HR Change Requests · Id: ID (trigger). • Required columns the action asks for: pick the SAME field from the trigger (it writes back what is already there). • Do not set Status or ApprovalStatus here — column defaults cover intake and Flow 5 owns approvals. | G23: Title (fx): concat(triggerBody()?['ChangeType']?['Value'], ' — ', triggerBody()?['EmployeeName']) RequestId (fx): outputs('Request_ID') RequestedBy Claims (fx): triggerBody()?['Author']?['Email'] SLADueDate (fx): outputs('SLA_Due_Date') NextActionDue (fx): outputs('SLA_Due_Date') PayPeriod (fx): if(equals(outputs('Code'), 'I'), outputs('Pay_Period'), '') AfterCutoff (fx): outputs('After_Cutoff') | H23: Item shows Request = 'E — Personal Data Change — <name>' and Request ID HRC-00000N. | I23: Johanna | J23: Not started
A24: S1-06 | B24: S1 | C24: Flow 1 | D24: Default assignee (from Change Types) | E24: Inside Try → Control → Condition 'Default assignee?' | F24: • Left (fx) and(empty(triggerBody()?['Assignee']), not(empty(coalesce(outputs('Config')?['DefaultAssigneeEmail'], '')))) · is equal to · (fx) true • True → Update item 'Set default assignee' (required columns from trigger). | G24: Assignee Claims (fx): outputs('Config')?['DefaultAssigneeEmail'] | H24: A G request gets CJ as Assignee. | I24: Johanna | J24: Not started
A25: S1-07 | B25: S1 | C25: Flow 1 | D25: Intake comment on the thread | E25: Inside Try — Comment pattern (Appendix B) | F25: • Add 'Display Name' Compose first (used by Slack too). Then the Comment pattern named 'Intake'. | G25: Display Name (Compose): if(equals(outputs('Config')?['Sensitive'], 'Yes'), '(confidential — see list)', triggerBody()?['EmployeeName']) Intake text (Compose): 📥 @{outputs('Request_ID')} received from @{triggerBody()?['Author']?['DisplayName']}. SLA target: @{coalesce(outputs('SLA_Due_Date'), outputs('Config')?['SLATarget'])}.@{if(outputs('After_Cutoff'), ' ⚠️ Submitted after the payroll cutoff for this pay period.', '')} Post intake — Body (fx): setProperty(json('{}'), 'text', take(outputs('Intake_text'), 1900)) | H25: Comment appears in the item's Comments pane. | I25: Johanna | J25: Not started
A26: S1-08 | B26: S1 | C26: Flow 1 | D26: Ping the People Ops room | E26: Inside Try → Slack → Post message (V2) | F26: • Channel: People Ops room. Message text below. | G26: Message text: :inbox_tray: *New HR change request <@{triggerBody()?['{Link}']}|@{outputs('Request_ID')}>* @{triggerBody()?['ChangeType']?['Value']} — @{outputs('Display_Name')} Effective @{formatDateTime(triggerBody()?['EffectiveDate'], 'MMM d, yyyy')} • SLA target @{coalesce(outputs('SLA_Due_Date'), outputs('Config')?['SLATarget'])}@{if(outputs('After_Cutoff'), ' • :warning: after payroll cutoff', '')} | H26: Message posts; for A2/G the name shows '(confidential — see list)'. | I26: Johanna | J26: Not started
A27: S1-09 | B27: S1 | C27: Flow 1 | D27: Confirmation to the submitter | E27: Inside Try → Office 365 Outlook → Send an email (V2) | F27: • Wording sets expectations without promising a date. | G27: To (fx): triggerBody()?['Author']?['Email'] Subject: We've got your request: @{outputs('Request_ID')} Body: Hi @{triggerBody()?['Author']?['DisplayName']}, Thanks for using the HR front door. Your request @{outputs('Request_ID')} (@{triggerBody()?['ChangeType']?['Value']}) is in the People Ops queue. Target completion: @{coalesce(outputs('SLA_Due_Date'), outputs('Config')?['SLATarget'])}. This is an automatic confirmation — a team member will pick it up and keep you posted. Follow along here: @{triggerBody()?['{Link}']} People Ops | H27: Email arrives. | I27: Johanna | J27: Not started
A28: S1-10 | B28: S1 | C28: Flow 1 | D28: Add the Catch block | E28: Below Try (not inside) | F28: • Add the Try / Catch pattern (Appendix C). | G28: Catch (Control → Scope) → ⋯ → Configure run after: Try: ☑ has failed ☑ has timed out (☐ is successful) Failure alert (Office 365 Outlook → Send an email (V2)) — To: your admin email (type it — don't depend on Settings here) Subject: [HR Change] @{workflow()?['tags']?['flowDisplayName']} failed Body: Open the failed run: @{concat('https://make.powerautomate.com/environments/', workflow()?['tags']?['environmentName'], '/flows/', workflow()?['name'], '/runs/', workflow()?['run']?['name'])} Flag the item (SharePoint → Update item, item-triggered flows only) — AutomationNote (fx): concat('⚠️ ', workflow()?['tags']?['flowDisplayName'], ' failed ', formatDateTime(utcNow(), 'yyyy-MM-dd HH:mm'), ' UTC — see admin email') | H28: Configure run after shows only 'has failed' and 'has timed out'. | I28: Johanna | J28: Not started
A29: S1-11 | B29: S1 | C29: Test | D29: Test Flow 1 | E29: Test → Manually → create an E request | F29: • Run T01 and T02 from the Test Pack. | H29: T01, T02 = Pass. | I29: Johanna | J29: Not started
A30: S1-12 | B30: S1 | C30: Flow 2 | D30: Create 'HR Change - 2 Checklist Router' | E30: Automated cloud flow | F30: • Trigger: SharePoint — When an item is created · List: HR Change Requests. (Separate from Flow 1 on purpose: one failing can't stop the other.) • Add Scope 'Try' and the Standard opening block inside it. | G30: Settings row (Excel Online (Business) → List rows present in a table): Location: your People Ops site · Document Library: Documents · File: HR Change/HR Change Reference.xlsx · Table: tblSettings Settings (Compose): first(outputs('Settings_row')?['body/value']) Code (Compose): first(split(triggerBody()?['ChangeType']?['Value'], ' ')) Change type row (Excel → List rows present in a table) — Table: tblChangeTypes · Filter Query:: Code eq '@{outputs('Code')}' Config (Compose): first(outputs('Change_type_row')?['body/value']) Request ID (Compose): concat(outputs('Settings')?['RequestPrefix'], formatNumber(triggerBody()?['ID'], '000000')) | H30: Saved. | I30: Johanna | J30: Not started
A31: S1-13 | B31: S1 | C31: Flow 2 | D31: Read this change type's checklist | E31: Inside Try | F31: • Excel → List rows present in a table 'Checklist rows': Table tblChecklist, Filter Query and Order By below. • Data Operation → Filter array 'Active steps', advanced mode. | G31: Checklist rows — Filter Query: Code eq '@{outputs('Code')}' Checklist rows — Order By: Step Active steps — From (fx): outputs('Checklist_rows')?['body/value'] Active steps — advanced mode: @equals(item()?['Active'], 'Yes') | H31: For E: Active steps returns 5 rows. | I31: Johanna | J31: Not started
A32: S1-14 | B32: S1 | C32: Flow 2 | D32: Build the checklist and post it | E32: Inside Try → Condition 'Has checklist' | F32: • Left (fx) length(body('Active_steps')) · is greater than · 0. • True branch: two Selects (Map in text mode — the T icon), one Compose, Update item, Comment pattern 'Checklist'. | G32: Checklist lines — Select From (fx): body('Active_steps') Checklist lines — Map (fx): concat('[ ] ', item()?['Step'], '. ', item()?['Task'], if(equals(item()?['AfterApproval'], 'Yes'), ' 🔒', ''), if(equals(item()?['DueOnLastDay'], 'Yes'), concat(' 📅 ', formatDateTime(coalesce(triggerBody()?['LastDay'], triggerBody()?['EffectiveDate']), 'MMM d')), ''), if(empty(item()?['Auto']), '', concat(' ⚙ ', item()?['Auto']))) Comment lines — Select From (fx): body('Active_steps') Comment lines — Map (fx): concat('☐ ', item()?['Step'], '. ', item()?['Task'], if(empty(item()?['Details']), '', concat(' — ', item()?['Details']))) Checklist text (Compose, fx): join(body('Checklist_lines'), decodeUriComponent('%0A')) Save checklist (Update item) — Checklist (fx): outputs('Checklist_text') Save checklist — ChecklistProgress: 0 Save checklist — NextAction (fx): concat(first(body('Active_steps'))?['Step'], '. ', first(body('Active_steps'))?['Task']) Checklist text for the thread — 'Checklist comment text' (Compose): 📋 @{outputs('Code')} checklist — @{length(body('Active_steps'))} steps. Tick them in the Checklist field by changing [ ] to [x]. @{join(body('Comment_lines'), decodeUriComponent('%0A'))} Post checklist comment — Body (fx): setProperty(json('{}'), 'text', take(outputs('Checklist_comment_text'), 1900)) | H32: E item: Checklist field has 5 '[ ]' lines; Next Action = '01. Confirm field(s) changing and new value'; checklist comment posted. | I32: Johanna | J32: Not started
A33: S1-15 | B33: S1 | C33: Flow 2 | D33: Catch-all for 'Other' | E33: Condition 'Has checklist' → False branch | F33: • Comment pattern 'No template' + Slack post to the People Ops room. | G33: No template text (Compose): ⚠️ No checklist for change type @{outputs('Code')} — needs manual scoping. Set an Assignee and write the steps into the Checklist field. Slack message: :warning: <@{triggerBody()?['{Link}']}|@{outputs('Request_ID')}> (@{triggerBody()?['ChangeType']?['Value']}) has no checklist — needs manual scoping. | H33: T04 passes. | I33: Johanna | J33: Not started
A34: S1-16 | B34: S1 | C34: Flow 2 | D34: Catch block + test | E34: Below Try | F34: • Add the Catch pattern. Run T03 and T04. | G34: Catch (Control → Scope) → ⋯ → Configure run after: Try: ☑ has failed ☑ has timed out (☐ is successful) Failure alert (Office 365 Outlook → Send an email (V2)) — To: your admin email (type it — don't depend on Settings here) Subject: [HR Change] @{workflow()?['tags']?['flowDisplayName']} failed Body: Open the failed run: @{concat('https://make.powerautomate.com/environments/', workflow()?['tags']?['environmentName'], '/flows/', workflow()?['name'], '/runs/', workflow()?['run']?['name'])} Flag the item (SharePoint → Update item, item-triggered flows only) — AutomationNote (fx): concat('⚠️ ', workflow()?['tags']?['flowDisplayName'], ' failed ', formatDateTime(utcNow(), 'yyyy-MM-dd HH:mm'), ' UTC — see admin email') | H34: T03, T04 = Pass. | I34: Johanna | J34: Not started
A35: S1-17 | B35: S1 | C35: Flow 4 | D35: Create 'HR Change - 4 Completion Auto-Comment' | E35: Automated cloud flow | F35: • Trigger: SharePoint — When an item is created or modified · List: HR Change Requests. • Trigger ⋯ → Settings → Trigger conditions (two lines). They make it fire once per resolution — the flow stamps Completion Date, so its own update can't re-fire it. • Add Scope 'Try' + opening block (you can skip 'Request ID'). | G35: Trigger condition 1: @equals(triggerBody()?['Status']?['Value'], '3-Resolved') Trigger condition 2: @empty(triggerBody()?['CompletionDate']) Settings row (Excel Online (Business) → List rows present in a table): Location: your People Ops site · Document Library: Documents · File: HR Change/HR Change Reference.xlsx · Table: tblSettings Settings (Compose): first(outputs('Settings_row')?['body/value']) Code (Compose): first(split(triggerBody()?['ChangeType']?['Value'], ' ')) Change type row (Excel → List rows present in a table) — Table: tblChangeTypes · Filter Query:: Code eq '@{outputs('Code')}' Config (Compose): first(outputs('Change_type_row')?['body/value']) | H35: Saved. | I35: Johanna | J35: Not started
A36: S1-18 | B36: S1 | C36: Flow 4 | D36: Work out outcome, resolver and the ticked checklist | E36: Inside Try | F36: • Compose × 4, Select × 1, Filter array × 1. | G36: Outcome: coalesce(triggerBody()?['Outcome']?['Value'], 'Completed') Resolver: coalesce(triggerBody()?['Assignee']?['DisplayName'], triggerBody()?['Editor']?['DisplayName']) Today: convertFromUtc(utcNow(), outputs('Settings')?['TimeZone']) Checklist before: split(replace(coalesce(triggerBody()?['Checklist'], ''), decodeUriComponent('%0D'), ''), decodeUriComponent('%0A')) Checklist after — Select From (fx) / Map (fx): outputs('Checklist_before') · if(and(startsWith(item(), '[ ]'), or(contains(item(), '⚙ resolution'), not(equals(outputs('Outcome'), 'Completed')))), concat(if(equals(outputs('Outcome'), 'Completed'), '[x]', '[–]'), substring(item(), 3)), item()) Still open — Filter array From (fx) / advanced: body('Checklist_after') · @startsWith(item(), '[ ]') | H36: On an E resolve: Checklist after shows steps 03–05 as [x]. | I36: Johanna | J36: Not started
A37: S1-19 | B37: S1 | C37: Flow 4 | D37: Stamp completion and post ✅ | E37: Inside Try | F37: • Update item 'Stamp completion' (required columns from trigger), then Comment pattern 'Resolved'. | G37: CompletionDate (fx): formatDateTime(outputs('Today'), 'yyyy-MM-dd') Outcome Value (fx): outputs('Outcome') Checklist (fx): if(empty(triggerBody()?['Checklist']), '', join(body('Checklist_after'), decodeUriComponent('%0A'))) NextAction (fx): '' Resolved text (Compose): ✅ Resolved on @{formatDateTime(outputs('Today'), 'MMM d, yyyy')} by @{outputs('Resolver')}@{if(equals(outputs('Outcome'), 'Completed'), '', concat(' (Outcome: ', outputs('Outcome'), ')'))}@{if(greater(length(body('Still_open')), 0), concat(' — note: ', string(length(body('Still_open'))), ' checklist step(s) were still open'), '')} | H37: Comment reads '✅ Resolved on <date> by <assignee>'. | I37: Johanna | J37: Not started
A38: S1-20 | B38: S1 | C38: Flow 4 | D38: Close-the-loop + People Ops summary | E38: Inside Try | F38: • Condition 'Close the loop?': Left (fx) or(equals(outputs('Config')?['CloseLoopEmail'], 'Yes'), not(equals(outputs('Outcome'), 'Completed'))) · is equal to · (fx) true → Send an email (V2). • Condition 'Summary to People Ops?': Left (fx) equals(outputs('Config')?['PostSummaryToPeopleOps'], 'Yes') · is equal to · (fx) true → Slack Post message (V2) to the People Ops room. | G38: Email To (fx): coalesce(triggerBody()?['RequestedBy']?['Email'], triggerBody()?['Author']?['Email']) Email Subject: Update on your HR request @{triggerBody()?['RequestId']} Email Body: Hi @{coalesce(triggerBody()?['RequestedBy']?['DisplayName'], triggerBody()?['Author']?['DisplayName'])}, @{if(equals(outputs('Outcome'), 'Completed'), concat('Good news — your request ', triggerBody()?['RequestId'], ' (', triggerBody()?['ChangeType']?['Value'], ') is complete.'), concat('Your request ', triggerBody()?['RequestId'], ' (', triggerBody()?['ChangeType']?['Value'], ') was closed as ', outputs('Outcome'), '.'))} @{if(empty(triggerBody()?['ApprovalHistory']), '', concat('Approval notes: ', triggerBody()?['ApprovalHistory']))} Questions? Just reply in #lane-people-talent or open the request: @{triggerBody()?['{Link}']} People Ops Slack summary: :white_check_mark: *<@{triggerBody()?['{Link}']}|@{triggerBody()?['RequestId']}>* @{outputs('Code')} resolved by @{outputs('Resolver')} (@{outputs('Outcome')}).@{if(greater(length(body('Still_open')), 0), concat(' :warning: ', string(length(body('Still_open'))), ' step(s) still open.'), '')} | H38: T05 passes. | I38: Johanna | J38: Not started
A39: S1-21 | B39: S1 | C39: Flow 4 | D39: Catch block + test | E39: Below Try | F39: • Catch pattern. Run T05. | G39: Catch (Control → Scope) → ⋯ → Configure run after: Try: ☑ has failed ☑ has timed out (☐ is successful) Failure alert (Office 365 Outlook → Send an email (V2)) — To: your admin email (type it — don't depend on Settings here) Subject: [HR Change] @{workflow()?['tags']?['flowDisplayName']} failed Body: Open the failed run: @{concat('https://make.powerautomate.com/environments/', workflow()?['tags']?['environmentName'], '/flows/', workflow()?['name'], '/runs/', workflow()?['run']?['name'])} Flag the item (SharePoint → Update item, item-triggered flows only) — AutomationNote (fx): concat('⚠️ ', workflow()?['tags']?['flowDisplayName'], ' failed ', formatDateTime(utcNow(), 'yyyy-MM-dd HH:mm'), ' UTC — see admin email') | H39: T05 = Pass. | I39: Johanna | J39: Not started
A40: S1-22 | B40: S1 | C40: Test | D40: Live E submission | E40: Real request | F40: • Johanna submits one real Personal Data Change, works the checklist and resolves it (T06). | H40: Gate G1 checklist complete. | I40: Johanna | J40: Not started
A41: S2-01 | B41: S2 | C41: Flow 5 | D41: Create 'HR Change - 5 Approval Routing' | E41: Automated cloud flow | F41: • Trigger: When an item is created · List: HR Change Requests. • BEFORE the Try scope (variables can't live inside a scope): Initialize variable 'Outcome' (String) = Approved; Initialize variable 'History' (String) = empty. • Then Scope 'Try' + opening block. | G41: Settings row (Excel Online (Business) → List rows present in a table): Location: your People Ops site · Document Library: Documents · File: HR Change/HR Change Reference.xlsx · Table: tblSettings Settings (Compose): first(outputs('Settings_row')?['body/value']) Code (Compose): first(split(triggerBody()?['ChangeType']?['Value'], ' ')) Change type row (Excel → List rows present in a table) — Table: tblChangeTypes · Filter Query:: Code eq '@{outputs('Code')}' Config (Compose): first(outputs('Change_type_row')?['body/value']) Request ID (Compose): concat(outputs('Settings')?['RequestPrefix'], formatNumber(triggerBody()?['ID'], '000000')) | H41: Saved. | I41: Johanna | J41: Not started
A42: S2-02 | B42: S2 | C42: Flow 5 | D42: Read the approval chain | E42: Inside Try | F42: • Filter array 'Stages'; Condition 'Needs approval' (Left fx length(body('Stages')) · is greater than · 0). Everything below goes in its True branch. | G42: Stages — From (fx): split(replace(coalesce(outputs('Config')?['ApprovalChain'], ''), ' ', ''), '>') Stages — advanced: @not(empty(item())) | H42: For I: Stages = ["HR"]. For E: empty → nothing happens. | I42: Johanna | J42: Not started
A43: S2-03 | B43: S2 | C43: Flow 5 | D43: Mark the request as waiting | E43: True branch | F43: • Excel List rows 'Approvers rows' (Table tblApprovers, no filter). • Update item 'Mark pending' (required columns from trigger). | G43: ApprovalStatus Value: Pending Status Value: 2-Waiting WaitingOn Value: Approver | H43: Item shows 2-Waiting / Pending / Approver. | I43: Johanna | J43: Not started
...

Sheet Reusable Blocks
A1: Reusable blocks
A2: Built the same way in several flows. The steps say 'add the … block'.
A4: Block | B4: Action / field | C4: Value / expression
A5: Standard opening block | B5: Settings row (Excel Online (Business) → List rows present in a table) | C5: Location: your People Ops site · Document Library: Documents · File: HR Change/HR Change Reference.xlsx · Table: tblSettings
A6: Standard opening block | B6: Settings (Compose) | C6: first(outputs('Settings_row')?['body/value'])
A7: Standard opening block | B7: Code (Compose) | C7: first(split(triggerBody()?['ChangeType']?['Value'], ' '))
A8: Standard opening block | B8: Change type row (Excel → List rows present in a table) — Table: tblChangeTypes · Filter Query: | C8: Code eq '@{outputs('Code')}'
A9: Standard opening block | B9: Config (Compose) | C9: first(outputs('Change_type_row')?['body/value'])
A10: Standard opening block | B10: Request ID (Compose) | C10: concat(outputs('Settings')?['RequestPrefix'], formatNumber(triggerBody()?['ID'], '000000'))
A11: Comment pattern (post to the item's thread) | B11: <Name> text (Compose) — type the message; insert @{…} parts with fx | C11: e.g. 📥 @{outputs('Request_ID')} received.
A12: Comment pattern (post to the item's thread) | B12: Post <name> (SharePoint → Send an HTTP request to SharePoint) — Method | C12: POST
A13: Comment pattern (post to the item's thread) | B13: Uri | C13: _api/web/lists/getbytitle('HR Change Requests')/items(@{triggerBody()?['ID']})/Comments
A14: Comment pattern (post to the item's thread) | B14: Headers | C14: Accept = application/json;odata=nometadata · Content-Type = application/json;odata=nometadata
A15: Comment pattern (post to the item's thread) | B15: Body (fx) | C15: setProperty(json('{}'), 'text', take(outputs('<Name>_text'), 1900))
... A20: Try / Catch pattern | B20: Flag the item (SharePoint → Update item, item-triggered flows only) — AutomationNote (fx) | C20: concat('⚠️ ', workflow()?['tags']?['flowDisplayName'], ' failed ', formatDateTime(utcNow(), 'yyyy-MM-dd HH:mm'), ' UTC — see admin email')

Sheet Gates
A1: Gates
A2: Every line must be Passed before the next sprint starts.
A4: Sprint | B4: Gate | C4: Criterion | D4: Status | E4: Date | F4: Evidence / notes
A5: S0 | B5: G0 — Ready to build | C5: D3, D5, D6 confirmed by CJ | D5: Not started
A6: S0 | B6: G0 — Ready to build | C6: Field list signed off with Johanna | D6: Not started
A7: S0 | B7: G0 — Ready to build | C7: Reference workbook uploaded and Settings filled | D7: Not started
A8: S0 | B8: G0 — Ready to build | C8: List built: all columns, choices, required fields, show/hide formulas, views | D8: Not started
A9: S0 | B9: G0 — Ready to build | C9: T21 passed (non-HR account sees only own requests) | D9: Not started
A10: S1 | B10: G1 — Plumbing proven | C10: T01–T06 pass | D10: Not started
A11: S1 | B11: G1 — Plumbing proven | C11: One live E submission by Johanna closed end to end | D11: Not started
A12: S1 | B12: G1 — Plumbing proven | C12: A failure alert email received from a Catch block (any test) | D12: Not started
A13: S1 | B13: G1 — Plumbing proven | C13: Flows owned by the HR/service account, not a personal one | D13: Not started
A14: S2 | B14: G2 — Front door live | C14: T07–T13 pass | D14: Not started
A15: S2 | B15: G2 — Front door live | C15: First real I case approved, earning entered, resolved, Payroll FYI posted | D15: Not started
A16: S2 | B16: G2 — Front door live | C16: Form pinned in #lane-people-talent; manager comms sent | D16: Not started
... A28: S6 | B28: Ongoing | C28: Each item ships with its own test cases and a rollback note | D28: Not started

Sheet Test Pack
A1: Test Pack (UAT)
A2: Run in the sprint shown. Record the result.
A4: ID | B4: Sprint | C4: Scenario | D4: How | E4: Expected | F4: Result | G4: Tested by | H4: Date | I4: Notes
A5: T01 | B5: S1 | C5: E — basic intake | D5: Submit an E request on a weekday. | E5: Request = 'E — Personal Data Change — <name>'; Request ID HRC-00000N; SLA = next business day; 📥 comment; People Ops Slack ping; confirmation email. | F5: Not run
A6: T02 | B6: S1 | C6: Weekend SLA | D6: Submit an E request on Saturday (or check SLA Start in the run of a Friday-evening test). | E6: Saturday submission → SLA = Tuesday (counting starts Monday). | F6: Not run
A7: T03 | B7: S1 | C7: E checklist | D7: Look at the T01 item. | E7: Checklist has 5 '[ ] 0n.' lines; 03–05 end with '⚙ resolution'; Next Action = '01. Confirm field(s) changing and new value'; 📋 comment lists the steps. | F7: Not run
A8: T04 | B8: S1 | C8: Other — catch-all | D8: Submit Change Type = Other. | E8: No checklist; '⚠️ … needs manual scoping' comment; Slack warning. | F8: Not run
A9: T05 | B9: S1 | C9: Resolve E | D9: Set Assignee = you, Status = 3-Resolved. | E9: Completion Date = today; Outcome = Completed; 03–05 ticked [x]; '✅ Resolved on <date> by <you>' (+ note if 01–02 were open); close-the-loop email. | F9: Not run
A10: T06 | B10: S1 | C10: Live E | D10: Johanna submits and works a real E request. | E10: Same as T01–T05 with no manual fixes. | F10: Not run
A11: T07 | B11: S2 | C11: I — HR approval (approve) | D11: Submit I: Rate Type Hourly, $100, first date worked in the current pay period before cutoff. | E11: 2-Waiting / Pending / Waiting On Approver; HR approval email; approve → Approved, step 01 [x], 🔓 comment; Status 0-New (no Assignee) or 1-Assigned. | F11: Not run
A12: T08 | B12: S2 | C12: I — after cutoff | D12: Submit I with first date worked in a pay period whose cutoff has passed. | E12: Pay Period label set; Submitted After Cutoff = Yes; ⚠️ in comment and Slack. | F12: Not run
A13: T09 | B13: S2 | C13: I — HR rejects | D13: Submit I; reject with a comment. | E13: Status 3-Resolved; Outcome Rejected; open steps [–]; rejection email with approval notes; NO Payroll FYI. | F13: Not run
A14: T10 | B14: S2 | C14: I — Payroll FYI | D14: Resolve the T07 request. | E14: Payroll room message once; Payroll Notified On = today; editing the item again does not re-post. | F14: Not run
A15: T11 | B15: S2 | C15: G — LOA | D15: Submit G with an expected return date. | E15: SLA blank ('Per policy' in comment); Assignee = CJ; Slack shows '(confidential — see list)'; ticking every step does not resolve it. | F15: Not run
A16: T12 | B16: S2 | C16: A1 — voluntary offboarding | D16: Submit A1 with Last Day next Friday. | E16: SLA Due Date = Last Day; 16 steps; 'Terminate in Paycor' line shows 📅 <last day>. | F16: Not run
... A26: T22 | B26: S3 | C26: Config without flow edits | D26: Change E's SLABusinessDays to 2 in Excel; submit E. | E26: SLA = 2 business days. Restore to 1. | F26: Not run

Sheet Decisions
A1: Decisions
A2: Design decisions and the ones that need your confirmation.
A4: ID | B4: Topic | C4: Decision | D4: Why | E4: Status
A5: D1 | B5: System of record | C5: Replace the HR Change Slack List with ONE SharePoint list: HR Change Requests. | D5: Your direction. One place per case; filterable views; works with Power Automate natively. | E5: Decided
A6: D2 | B6: Reference data | C6: SLAs, approval chains, checklists, approvers and settings live as tables in one Excel workbook (HR Change Reference.xlsx) that the flows read. | D6: Manage them like a reference sheet, without extra lists or flow edits. Contract: never rename a table or a column header. | E6: Decided
A7: D3 | B7: Front door | C7: The list's New form is the front door, pinned in #lane-people-talent. Microsoft Forms is reserved for the Phase 3 manager self-service form. | D7: A Slack Workflow Builder form cannot write to SharePoint without a bot token or webhook app. Principle update: 'Microsoft-native for the record, Slack for visibility'. | E7: Confirm (CJ)
A8: D4 | B8: Checklist / subtasks | C8: The checklist is posted to the item's comment thread (the work log) AND written to an editable Checklist field. HR ticks [ ] → [x]; a flow keeps Checklist % and Next Action current. | D8: Delivers Phase 1 (thread checklist) and the Phase 2 goal (progress visibility) without a second list. | E8: Decided
A9: D5 | B9: Template I — Payroll role | C9: Payroll is a verifier, not a gate: a one-way Slack FYI when People Ops resolves an I case. | D9: The plan's Flow 3 section says this explicitly; the master reference's 'Payroll final approval' line conflicts. To make Payroll a gate later, add 'Payroll' to I's ApprovalChain. | E9: Confirm (CJ)
A10: D6 | B10: Manager field | C10: 'Manager Name' becomes a Manager person field. | D10: Approvals need an email to route to. | E10: Confirm (Johanna)
A11: D7 | B11: Comp 'approval confirmed (Y/N)' | C11: Retired. Replaced by the in-system approval chain. | D11: One source of truth for approval. | E11: Decided
A12: D8 | B12: Approvals channel | C12: Power Automate Approvals (email, Teams, Power Automate app). In-Slack approve buttons wait for the Phase 3 bot token. | D12: Standard connector, no IT app approval. | E12: Decided
A13: D9 | B13: Slack connection | C13: Power Automate Slack connector (OAuth) under a People Ops service account. Posts go to channels. | D13: Answers the plan's open question: no bot token needed. DMs need member IDs, so channels for now. | E13: Decided
A14: D10 | B14: Status model | C14: Keep Tag, You're It (0-New, 1-Assigned, 2-Waiting, 3-Resolved). Add Waiting On, Next Action, Next Action Due, Outcome. | D14: Keeps continuity; adds 'who/what/when' for every active case (from the inspiration). | E14: Decided
A15: D11 | B15: Sensitive change types | C15: A2 and G (and optionally H) withhold the employee name from Slack and the digest. Item-level permissions on the list. | D15: Limit sensitive content in notifications. | E15: Decided
... A17: D13 | B17: Approval rollout | C17: I's HR approval goes live in Sprint 2 (pilot). B, C, F chains are switched on in Sprint 3 by filling ApprovalChain in Excel after the matrix is signed off. | D17: Matches the dependency 'Approval matrix signed off by stakeholders'. | E17: Decided
A18: D14 | B18: Plan typo | C18: 'deparHRent' → 'department' (looks like a find/replace of 'tm' → 'HR'). Check the source doc for other damaged words. | E18: FYI
A19: D15 | B19: Template I pilot cases | C19: The ICS live examples (DVA $100/hr, $800/day, first days Aug 15) have passed. Pilot with the next real I submission. | E19: FYI

Sheet Inspiration Review
A1: Inspiration Review
A2: What we adopted, adapted, deferred or rejected from the email-ticketing inspiration — and why.
A4: Idea | B4: Verdict | C4: Why | D4: How it shows up
A5: Email-first intake (employees keep emailing HR) | B5: Reject | C5: Breaks 'One front door' and 'Not in the intake, does not exist'. | D5: Adapt instead: an auto-reply on the HR mailbox that points people to the form (Sprint 2, no flow needed).
A6: Ticket-marker matching on email replies | B6: Reject (for now) | C6: Only needed with email intake. | D6: The earlier hr-ticketing-triage solution keeps this if email intake is ever wanted.
A7: One accountable owner + Next action + Next action date on every active case | B7: Adopt | C7: Directly improves Tag, You're It: 'In progress' alone doesn't say what happens next. | D7: Next Action / Next Action Due fields; Flow 6 keeps Next Action = first open checklist step.
A8: Richer status set (waiting on employee / third party) | B8: Adapt | C8: Keep the 0–3 labels for continuity. | D8: Add a Waiting On field used with 2-Waiting.
A9: First human response date | B9: Defer | C9: Your SLAs measure completion, not first response. | D9: Revisit in Run phase for reporting.
A10: Action-based workbench views | B10: Adopt | C10: Fast daily triage. | D10: 8 views (see Views tab), incl. Needs Attention Today and Exceptions.
A11: Daily digest instead of per-update emails | B11: Adopt | C11: Less noise; one place to see risk. | D11: Flow 7 (Sprint 4), sensitive names withheld.
A12: Separate restricted lane for sensitive casework | B12: Adapt | C12: HR change requests are mostly routine; LOA/offboarding need care, ER investigations are out of scope. | D12: Sensitive flag per change type + item-level permissions now; restricted ER area is a Run-phase decision.
A13: Copy email bodies/attachments into the ticket; Ticket Messages list | B13: Reject | C13: One-list rule; the comment thread is the log. | D13: Attachments go on the list item directly when needed.
A14: Send HR responses from list fields | B14: Reject | C14: Complexity and risk for little gain. | D14: Reply in Slack/Outlook; close-the-loop email is automated at resolution.
A15: Auto-close after inactivity | B15: Reject | C15: LOA must stay open; closure is a deliberate HR act in your plan. | D15: Daily digest surfaces stale items instead.
... A20: Test access with a non-HR account before launch | B20: Adopt | C20: Filtered views are not security. | D20: Gate 0 / test T21.

Sheet Plan Traceability
A1: Plan Traceability
A2: Every element of the project plan and where it is delivered.
A4: Project plan item | B4: Where it lives in the build | C4: Sprint
A5: Guiding principle — One front door | B5: List New form pinned in #lane-people-talent; HR mailbox auto-reply points to it | C5: S0, S2
A6: Guiding principle — Not in the intake, does not exist | B6: Every case is an item; digest + views only show list items | C6: S2
A7: Guiding principle — Slack native first | B7: Updated (D3): Microsoft-native for the record, Slack for visibility | C7: S0
A8: Guiding principle — The list is the system of record | B8: ONE SharePoint list: HR Change Requests | C8: S0
A9: Guiding principle — Templates do the thinking | B9: Checklists table (A1–I) → Flow 2 Checklist Router | C9: S1
A10: Guiding principle — The thread is the work log | B10: Item Comments: intake, checklist, approvals, resolution all logged | C10: S1
A11: Guiding principle — Offboarding is a path | B11: A1/A2 are change types on the same list and engine | C11: S2
A12: Layer 1 — Intake form + confirmation to submitter | B12: List form + Flow 1 Intake Notification (confirmation email, People Ops ping) | C12: S1
A13: Layer 2 / Phase 1 — Thread-based checklist | B13: Flow 2 posts the checklist as an item comment | C13: S1
A14: Layer 2 / Phase 2 — True subtasks + progress | B14: Checklist field with [ ]/[x] + Flow 6 Checklist % and Next Action | C14: S3
A15: Master template items never completed | B15: Checklists table in the reference workbook (SOP source of truth) | C15: S0
... A36: Open question — Slack app vs Power Automate connector | B36: Answered: connector (D9) | C36: S0

Sheet Dependencies
A1: Dependencies
A2: From the plan's dependencies table, plus what this build adds.
A4: Item | B4: Owner | C4: Status | D4: Needed by | E4: Notes
A5: HR Change Reference.xlsx stored on the People Ops site | B5: CJ | C5: Ready (this kit) | D5: S0 | E5: Flows read it.
A6: Slack connection under a People Ops service account | B6: CJ / IT | C6: To confirm | D6: S0 | E6: Messages appear from this account.
A7: Field list signed off | B7: Johanna | C7: To confirm | D7: S0 | E7: Gate 0.
A8: Approval matrix signed off by stakeholders | B8: CJ | C8: To confirm | D8: S3 | E8: Gate 3: switches on B, C, F approvals.
A9: Jira connector access in Power Automate + HR Jira project | B9: IT | C9: To confirm | D9: S5 | E9: Plan open question.
A10: Shared offboarding email distro exists and is current | B10: CJ / Johanna | C10: To confirm | D10: S5 | E10: Plan open question.
A11: Word termination letter template (content controls) | B11: CJ | C11: To build | D11: S5 | E11: 'Populate a Microsoft Word template' is a premium connector action.
A12: Monday backfill request form URL | B12: Talent | C12: To confirm | D12: S5
A13: Payroll Monday board — column/item to post to | B13: Sydney / Sandra | C13: To confirm | D13: S5 | E13: Plan open question.
A14: Paycor bot token / iPaaS | B14: IT / Paycor CSM | C14: Pending | D14: S6 | E14: Run phase.

Sheet Comms
A1: Launch comms (Sprint 2)
A2: Replace <IntakeFormUrl> with the real link.
A4: Where | B4: Text
A5: #lane-people-talent announcement (pin it) | B5: 📣 *New: one front door for HR changes* From today, every HR change request (offboarding, job/status, comp, pay/banking, personal data, time/PTO, LOA, benefits, extra shifts) goes through this form: <IntakeFormUrl> • You'll get a confirmation with a request ID and a target date. • If it needs approval, the approver gets it automatically. • You'll hear back when it's done. Requests sent by DM or email will be pointed back here — if it isn't in the intake, we can't track it. Thank you! — People Ops
A6: HR mailbox automatic reply | B6: Thanks for reaching out to People Ops. HR change requests are handled through our request form so nothing gets lost: <IntakeFormUrl>. For anything else, a member of the team will reply soon.
